Workbook

Sheet Assumptions
A1: ASSUMPTIONS — edit any yellow cell. Model recalculates everywhere.
A2: All inputs are tuneable. Cells with yellow background are editable. White cells are computed.
A4: Creator subscription tier MIX (% of registered creators)
A5: Maker share | B5: 0.7
A6: Builder share | B6: 0.25
A7: Agency share | B7: 0.05
A8: Sum check | B8: =SUM(B5:B7) -> 1
A10: Activation rate per tier (% who order monthly)
A11: Maker activation | B11: 0.3 | D11: Conservative override | E11: 0.15
A12: Builder activation | B12: 0.7 | E12: 0.35
A13: Agency activation | B13: 0.9 | E13: 0.45
A15: On-demand orders per active creator per month
A16: Maker orders/mo | B16: 5 | D16: Conservative | E16: 2
A17: Builder orders/mo | B17: 80 | E17: 40
A18: Agency orders/mo | B18: 400 | E18: 200
A20: Bulk orders — runs/mo + avg run size
A21: Maker bulk runs/mo | B21: 0.1 | C21: size | D21: 200 | F21: Conservative runs | G21: 0.05
A22: Builder bulk runs/mo | B22: 0.5 | C22: size | D22: 800 | G22: 0.25
A23: Agency bulk runs/mo | B23: 2 | C23: size | D23: 3000 | G23: 1
A25: Subscription pricing (monthly)
A26: Builder $/mo (original $49 → rebuilt $79) | B26: 79
A27: Agency $/mo (original $199 → rebuilt $249) | B27: 249
A30: Velocity-tier fee % (subscription × velocity tier matrix)
A31: Tier | B31: Volume | C31: Maker | D31: Builder | E31: Agency
A32: Tier 1 | B32: 0-50 | C32: 0.15 | D32: 0.1 | E32: 0.07
A33: Tier 2 | B33: 51-200 | C33: 0.13 | D33: 0.085 | E33: 0.06
A34: Tier 3 | B34: 201-500 | C34: 0.11 | D34: 0.07 | E34: 0.05
A35: Tier 4 | B35: 501-1000 | C35: 0.09 | D35: 0.06 | E35: 0.05
A36: Tier 5 | B36: 1000+ | C36: 0.07 | D36: 0.05 | E36: 0.05
A38: Velocity tier DISTRIBUTION (% of active creators per sub tier)
A39: Tier | B39: Maker | C39: Builder | D39: Agency | F39: Conservative
A40: Tier 1 | B40: 0.9 | C40: 0.55 | D40: 0.3 | F40: 0.95 | G40: 0.7 | H40: 0.5
A41: Tier 2 | B41: 0.08 | C41: 0.25 | D41: 0.3 | F41: 0.04 | G41: 0.2 | H41: 0.3
A42: Tier 3 | B42: 0.02 | C42: 0.12 | D42: 0.2 | F42: 0.01 | G42: 0.07 | H42: 0.15
A43: Tier 4 | B43: 0 | C43: 0.06 | D43: 0.12 | F43: 0 | G43: 0.02 | H43: 0.04
A44: Tier 5 | B44: 0 | C44: 0.02 | D44: 0.08 | F44: 0 | G44: 0.01 | H44: 0.01
A47: Order economics
A48: On-demand retail AOV | B48: 30
A49: On-demand partner wholesale | B49: 8
A50: On-demand shipping est | B50: 4.5
...

Sheet Tier Model
A1: Rebuilt Tier Model — pricing references Assumptions sheet
B3: Maker | C3: Builder | D3: Agency
A4: Monthly subscription | B4: =0 -> 0 | C4: =Assumptions!B26 -> 79 | D4: =Assumptions!B27 -> 249
A5: Velocity Tier 1 fee | B5: =Assumptions!C32+Assumptions!B79/100 -> 0.15 | C5: =Assumptions!D32+Assumptions!B79/100 -> 0.1 | D5: =Assumptions!E32+Assumptions!B79/100 -> 0.07
A6: Velocity Tier 2 fee | B6: =Assumptions!C33+Assumptions!B79/100 -> 0.13 | C6: =Assumptions!D33+Assumptions!B79/100 -> 0.085 | D6: =Assumptions!E33+Assumptions!B79/100 -> 0.06
A7: Velocity Tier 3 fee | B7: =Assumptions!C34+Assumptions!B79/100 -> 0.11 | C7: =Assumptions!D34+Assumptions!B79/100 -> 0.07 | D7: =Assumptions!E34+Assumptions!B79/100 -> 0.05
A8: Velocity Tier 4 fee (floor 5%) | B8: =Assumptions!C35+Assumptions!B79/100 -> 0.09 | C8: =Assumptions!D35+Assumptions!B79/100 -> 0.06 | D8: =Assumptions!E35+Assumptions!B79/100 -> 0.05
A9: Velocity Tier 5 fee (floor 5%) | B9: =Assumptions!C36+Assumptions!B79/100 -> 0.07 | C9: =Assumptions!D36+Assumptions!B79/100 -> 0.05 | D9: =Assumptions!E36+Assumptions!B79/100 -> 0.05
A10: Effective fee (vol-weighted) | B10: =SUMPRODUCT(Assumptions!C32:C36+Assumptions!B79/100,Assumptions!B40:B44) -> 0.1476 | C10: =SUMPRODUCT(Assumptions!D32:D36+Assumptions!B79/100,Assumptions!C40:C44) -> 0.08925 | D10: =SUMPRODUCT(Assumptions!E32:E36+Assumptions!B79/100,Assumptions!D40:D44) -> 0.059
A11: Bulk orders allowed | B11: YES | C11: YES | D11: YES
A12: On-demand orders allowed | B12: YES | C12: YES | D12: YES
A13: AI parser quota / mo | B13: — | C13: =Assumptions!B68 -> 50 | D13: =Assumptions!B69 -> 200
A14: Brands per account | B14: 1 | C14: 3 | D14: Unlimited

Sheet Partner Tiers
A1: Partner tier ladder — Verified → Trusted → Anchor
A2: Three-step narrative arc: arrival → commitment → pillar. ALL THREE tiers FREE in V1.5 — no partner subscription anywhere. Tier progression is admin-promoted at every step based on performance. Lower per-order fee at higher tier is the reward. V2 may revisit subscription when advanced tools ship.
B4: Verified | C4: Trusted | D4: Anchor
A5: Tier means | B5: Arrival | C5: Commitment (earned) | D5: Pillar (earned)
A6: How to reach it | B6: Pass application + KYB | C6: Admin-promoted on performance | D6: Admin-promoted / invite-only
A7: Per-order fee % of partner wholesale | B7: =Assumptions!B55 -> 0.05 | C7: =Assumptions!B56 -> 0.035 | D7: =Assumptions!B57 -> 0.02
A8: Monthly subscription cost (V1.5) | B8: 0 | C8: 0 | D8: 0
A9: Self-serve onboarding | B9: YES | C9: Admin promotes | D9: Invite-only
A10: Basic Partner Product Builder | B10: YES | C10: YES | D10: YES
A11: Order accept/decline + payouts | B11: YES | C11: YES | D11: YES
A12: FDA compliance scan | B12: YES | C12: YES | D12: YES
A13: Marketplace placement boost | B13: Standard | C13: Modest | D13: Premium
A14: Marketplace badge | B14: Verified | C14: Trusted | D14: Anchor
A15: Promotion criteria | B15: Pass app | C15: Volume + reliability + on-time | D15: Scale + strategic value
A16: V2 forward-pointer: advanced tools | B16: — | C16: TBD — gate-by-tier OR sub overlay | D16: TBD — gate-by-tier OR sub overlay
A17: Tier mix assumption | B17: =Assumptions!B58 -> 0.7 | C17: =Assumptions!B59 -> 0.25 | D17: =Assumptions!B60 -> 0.05
A19: Volume-weighted partner fee % (avg) | B19: =Assumptions!B55*Assumptions!B58+Assumptions!B56*Assumptions!B59+Assumptions!B57*Assumptions!B60 -> 0.04475
A21: Example: 1,000-unit on-demand order @ $8 wholesale
A22: Partner wholesale revenue (gross) | B22: =1000*Assumptions!B49 -> 8000
A23: Verified partner fee (5%) | B23: =1000*Assumptions!B49*Assumptions!B55 -> 400
A24: Trusted partner fee (3.5%) | B24: =1000*Assumptions!B49*Assumptions!B56 -> 280
A25: Anchor partner fee (2%) | B25: =1000*Assumptions!B49*Assumptions!B57 -> 160
A26: Anchor net (highest take-home) | B26: =B22-B25 -> 7840
A28: Design principles (LOCKED 2026-06-04)
A29: 1. Verified = arrival. Every approved partner starts free.
A30: 2. Trusted = commitment, EARNED through track record. No subscription required.
A31: 3. Anchor = pillar, EARNED through scale + strategic value. No subscription required.
A32: 4. ALL THREE tiers are FREE in V1.5 — no partner subscription anywhere.
A33: 5. ALL tier progression is admin-promoted on performance criteria.
A34: 6. Per-order fee differentiation (5% / 3.5% / 2%) is the only monetary reward for tier promotion.
A35: 7. Marketplace badges signal trust, never paid placement. Cannot be bought.
A36: 8. Essentials (order accept, payouts, basic builder, FDA scan) always free regardless of tier.
A37: 9. V2 may revisit a paid subscription overlay when advanced tools ship (3D Builder, AI agent, video gen).
A38: 10. Principle: V1.5 monetization must justify itself with a delivered feature that has platform fixed cost.

Sheet Bulk Tier
A1: Bulk Pricing — per-order quantity tier system (V1.5)
A2: Bulk uses per-order quantity tier (separate from on-demand velocity tier). Platform-suggested category brackets, partner-customizable wholesale prices. Tiers below MOQ render N/A. Maker gets full access at higher base fee rate.
A4: Platform fee on bulk (FLAT — not velocity-discounted)
A5: Tier | B5: Subscription | C5: Bulk platform fee % | D5: Bulk access
A6: Maker | B6: 0 | C6: =Assumptions!C32 -> 0.15 | D6: FULL (locked Pavel 2026-06-04)
A7: Builder | B7: =Assumptions!B26 -> 79 | C7: =Assumptions!D32 -> 0.1 | D7: FULL
A8: Agency | B8: =Assumptions!B27 -> 249 | C8: =Assumptions!E32 -> 0.07 | D8: FULL
A10: NOTE: Bulk fee % = the Tier-1 subscription tier rate from Assumptions sheet (flat, not velocity-discounted). Bulk's pricing leverage is the wholesale tier ladder below.
A13: Category bracket ladders (V1.5 suggested defaults — partner-customizable per product)
A14: Tier | B14: Supplements | C14: Beverages | D14: Snack food | E14: Pet products | F14: Cosmetics | G14: OTC pharma
A15: T1 | B15: 100–249 | C15: 500–999 | D15: 500–999 | E15: 100–499 | F15: 250–499 | G15: 1,000–4,999
A16: T2 | B16: 250–999 | C16: 1,000–4,999 | D16: 1,000–4,999 | E16: 500–1,999 | F16: 500–1,999 | G16: 5,000–19,999
A17: T3 | B17: 1,000–4,999 | C17: 5,000–19,999 | D17: 5,000–19,999 | E17: 2,000–9,999 | F17: 2,000–9,999 | G17: 20,000–49,999
A18: T4 | B18: 5,000–14,999 | C18: 20,000–49,999 | D18: 20,000–49,999 | E18: 10,000–29,999 | F18: 10,000–29,999 | G18: 50,000–99,999
A19: T5 | B19: 15,000–49,999 | C19: 50,000–99,999 | D19: 50,000–99,999 | E19: 30,000–99,999 | F19: 30,000–99,999 | G19: 100,000–249,999
A20: T6 | B20: 50,000+ | C20: 100,000+ | D20: 100,000+ | E20: 100,000+ | F20: 100,000+ | G20: 250,000+
A23: MOQ-anchored example — Supplements product with MOQ = 100
A24: Tier | B24: Qty range | C24: Status | D24: Partner wholesale $/unit | E24: + Platform fee (Maker 15%) | F24: + Platform fee (Builder 10%) | G24: + Platform fee (Agency 7%)
A25: T1 (below MOQ) | B25: 0–49 | C25: N/A | D25: — | E25: — | F25: — | G25: —
A26: T1 (below MOQ) | B26: 50–99 | C26: N/A | D26: — | E26: — | F26: — | G26: —
A27: T1 | B27: 100–249 | C27: ACTIVE | D27: 7.84 | E27: =D27*(1+Assumptions!C32) -> 9.016 | F27: =D27*(1+Assumptions!D32) -> 8.624 | G27: =D27*(1+Assumptions!E32) -> 8.3888
A28: T2 | B28: 250–499 | C28: ACTIVE | D28: 7.11 | E28: =D28*(1+Assumptions!C32) -> 8.1765 | F28: =D28*(1+Assumptions!D32) -> 7.821 | G28: =D28*(1+Assumptions!E32) -> 7.6077
A29: T3 | B29: 500–999 | C29: ACTIVE | D29: 6.74 | E29: =D29*(1+Assumptions!C32) -> 7.751 | F29: =D29*(1+Assumptions!D32) -> 7.414 | G29: =D29*(1+Assumptions!E32) -> 7.2118
A30: T4 | B30: 1,000–2,499 | C30: ACTIVE | D30: 6.43 | E30: =D30*(1+Assumptions!C32) -> 7.3945 | F30: =D30*(1+Assumptions!D32) -> 7.073 | G30: =D30*(1+Assumptions!E32) -> 6.8801
A31: T5 | B31: 2,500–4,999 | C31: ACTIVE | D31: 5.83 | E31: =D31*(1+Assumptions!C32) -> 6.7045 | F31: =D31*(1+Assumptions!D32) -> 6.413 | G31: =D31*(1+Assumptions!E32) -> 6.2381
A32: T6 | B32: 5,000+ | C32: ACTIVE | D32: 5.4 | E32: =D32*(1+Assumptions!C32) -> 6.21 | F32: =D32*(1+Assumptions!D32) -> 5.94 | G32: =D32*(1+Assumptions!E32) -> 5.778
A35: Worked example — 5,000-unit bulk run @ T6 wholesale ($5.40/unit)
A36: Quantity | B36: 5000
A37: Wholesale unit price | B37: =D32 -> 5.4
A38: Wholesale total | B38: =B36*B37 -> 27000
A39: Tier | B39: Platform fee % | C39: Platform fee $ | D39: Total creator cost | E39: Savings vs Maker
A40: Maker | B40: =Assumptions!C32 -> 0.15 | C40: =B38*B40 -> 4050 | D40: =B38+C40 -> 31050 | E40: =$D$40-D40 -> 0
A41: Builder | B41: =Assumptions!D32 -> 0.1 | C41: =B38*B41 -> 2700 | D41: =B38+C41 -> 29700 | E41: =$D$40-D41 -> 1350
A42: Agency | B42: =Assumptions!E32 -> 0.07 | C42: =B38*B42 -> 1890 | D42: =B38+C42 -> 28890 | E42: =$D$40-D42 -> 2160
A44: Locked decisions (2026-06-04) — see _V1.5_BULK_PRICING.md for full spec
A45: 1. Bulk and on-demand tier systems are SEPARATE
A46: 2. Cross-pollination YES — bulk volume accrues to SKU's on-demand velocity tier
A47: 3. Platform-suggested category brackets, partner-customizable
A48: 4. MOQ-anchored — tiers below MOQ render N/A
A49: 5. MaxOQ per batch — auto-split or route to another partner above ceiling
...

Sheet Results
A1: Results — live, formula-driven, 4 scales
A2: Change any Assumptions input and every cell here recalculates. Toggle scenario via Assumptions!B78 (conservative) and B79 (uplift).
A4: Metric | B4: 100 creators | C4: 1,000 creators | D4: 10,000 creators | E4: 30,000 creators
A5: Partners | B5: =ROUND(100/Assumptions!B62,0) -> 3 | C5: =ROUND(1000/Assumptions!B62,0) -> 25 | D5: =ROUND(10000/Assumptions!B62,0) -> 250 | E5: =ROUND(30000/Assumptions!B62,0) -> 750
A6: Registered Makers | B6: =ROUND(100*(IF(Assumptions!$B$82=1,Assumptions!B102,Assumptions!B5)),0) -> 70 | C6: =ROUND(1000*(IF(Assumptions!$B$82=1,Assumptions!B102,Assumptions!B5)),0) -> 700 | D6: =ROUND(10000*(IF(Assumptions!$B$82=1,Assumptions!B102,Assumptions!B5)),0) -> 7000 | E6: =ROUND(30000*(IF(Assumptions!$B$82=1,Assumptions!B102,Assumptions!B5)),0) -> 21000
A7: Registered Builders | B7: =ROUND(100*(IF(Assumptions!$B$82=1,Assumptions!B103,Assumptions!B6)),0) -> 25 | C7: =ROUND(1000*(IF(Assumptions!$B$82=1,Assumptions!B103,Assumptions!B6)),0) -> 250 | D7: =ROUND(10000*(IF(Assumptions!$B$82=1,Assumptions!B103,Assumptions!B6)),0) -> 2500 | E7: =ROUND(30000*(IF(Assumptions!$B$82=1,Assumptions!B103,Assumptions!B6)),0) -> 7500
A8: Registered Agencies | B8: =ROUND(100*(Assumptions!B7),0) -> 5 | C8: =ROUND(1000*(Assumptions!B7),0) -> 50 | D8: =ROUND(10000*(Assumptions!B7),0) -> 500 | E8: =ROUND(30000*(Assumptions!B7),0) -> 1500
A9: Active Makers | B9: =ROUND(100*(IF(Assumptions!$B$82=1,Assumptions!B102,Assumptions!B5))*(IF(Assumptions!$B$78=1,Assumptions!E11,Assumptions!B11)),0) -> 21 | C9: =ROUND(1000*(IF(Assumptions!$B$82=1,Assumptions!B102,Assumptions!B5))*(IF(Assumptions!$B$78=1,Assumptions!E11,Assumptions!B11)),0) -> 210 | D9: =ROUND(10000*(IF(Assumptions!$B$82=1,Assumptions!B102,Assumptions!B5))*(IF(Assumptions!$B$78=1,Assumptions!E11,Assumptions!B11)),0) -> 2100 | E9: =ROUND(30000*(IF(Assumptions!$B$82=1,Assumptions!B102,Assumptions!B5))*(IF(Assumptions!$B$78=1,Assumptions!E11,Assumptions!B11)),0) -> 6300
A10: Active Builders | B10: =ROUND(100*(IF(Assumptions!$B$82=1,Assumptions!B103,Assumptions!B6))*(IF(Assumptions!$B$82=1,MAX(IF(Assumptions!$B$78=1,Assumptions!E12,Assumptions!B12),Assumptions!B104),IF(Assumptions!$B$78=1,Assumptions!E12,Assumptions!B12))),0) -> 18 | C10: =ROUND(1000*(IF(Assumptions!$B$82=1,Assumptions!B103,Assumptions!B6))*(IF(Assumptions!$B$82=1,MAX(IF(Assumptions!$B$78=1,Assumptions!E12,Assumptions!B12),Assumptions!B104),IF(Assumptions!$B$78=1,Assumptions!E12,Assumptions!B12))),0) -> 175 | D10: =ROUND(10000*(IF(Assumptions!$B$82=1,Assumptions!B103,Assumptions!B6))*(IF(Assumptions!$B$82=1,MAX(IF(Assumptions!$B$78=1,Assumptions!E12,Assumptions!B12),Assumptions!B104),IF(Assumptions!$B$78=1,Assumptions!E12,Assumptions!B12))),0) -> 1750 | E10: =ROUND(30000*(IF(Assumptions!$B$82=1,Assumptions!B103,Assumptions!B6))*(IF(Assumptions!$B$82=1,MAX(IF(Assumptions!$B$78=1,Assumptions!E12,Assumptions!B12),Assumptions!B104),IF(Assumptions!$B$78=1,Assumptions!E12,Assumptions!B12))),0) -> 5250
A11: Active Agencies | B11: =ROUND(100*(Assumptions!B7)*(IF(Assumptions!$B$78=1,Assumptions!E13,Assumptions!B13)),0) -> 5 | C11: =ROUND(1000*(Assumptions!B7)*(IF(Assumptions!$B$78=1,Assumptions!E13,Assumptions!B13)),0) -> 45 | D11: =ROUND(10000*(Assumptions!B7)*(IF(Assumptions!$B$78=1,Assumptions!E13,Assumptions!B13)),0) -> 450 | E11: =ROUND(30000*(Assumptions!B7)*(IF(Assumptions!$B$78=1,Assumptions!E13,Assumptions!B13)),0) -> 1350
A12: Subscription revenue (mo) | B12: =ROUND(100*(IF(Assumptions!$B$82=1,Assumptions!B103,Assumptions!B6))*IF(Assumptions!$B$84=1,79,49)+100*(Assumptions!B7)*IF(Assumptions!$B$84=1,249,199),0) -> 2220 | C12: =ROUND(1000*(IF(Assumptions!$B$82=1,Assumptions!B103,Assumptions!B6))*IF(Assumptions!$B$84=1,79,49)+1000*(Assumptions!B7)*IF(Assumptions!$B$84=1,249,199),0) -> 22200 | D12: =ROUND(10000*(IF(Assumptions!$B$82=1,Assumptions!B103,Assumptions!B6))*IF(Assumptions!$B$84=1,79,49)+10000*(Assumptions!B7)*IF(Assumptions!$B$84=1,249,199),0) -> 222000 | E12: =ROUND(30000*(IF(Assumptions!$B$82=1,Assumptions!B103,Assumptions!B6))*IF(Assumptions!$B$84=1,79,49)+30000*(Assumptions!B7)*IF(Assumptions!$B$84=1,249,199),0) -> 666000
A14: On-demand units (mo) | B14: =ROUND(((100*(IF(Assumptions!$B$82=1,Assumptions!B102,Assumptions!B5))*(IF(Assumptions!$B$78=1,Assumptions!E11,Assumptions!B11)))*IF(Assumptions!$B$78=1,Assumptions!E16,Assumptions!B16)*(1-0.05)+(100*(IF(Assumptions!$B$82=1,Assumptions!B103,Assumptions!B6))*(IF(Assumptions!$B$82=1,MAX(IF(Assumptions!$B$78=1,Assumptions!E12,Assumptions!B12),Assumptions!B104),IF(Assumptions!$B$78=1,Assumptions!E12,Assumptions!B12))))*IF(Assumptions!$B$78=1,Assumptions!E17,Assumptions!B17)*(1-0.3)+(100*(Assumptions!B7)*(IF(Assumptions!$B$78=1,Assumptions!E13,Assumptions!B13)))*IF(Assumptions!$B$78=1,Assumptions!E18,Assumptions!B18)*(1-0.6)),0) -> 1800 | C14: =ROUND(((1000*(IF(Assumptions!$B$82=1,Assumptions!B102,Assumptions!B5))*(IF(Assumptions!$B$78=1,Assumptions!E11,Assumptions!B11)))*IF(Assumptions!$B$78=1,Assumptions!E16,Assumptions!B16)*(1-0.05)+(1000*(IF(Assumptions!$B$82=1,Assumptions!B103,Assumptions!B6))*(IF(Assumptions!$B$82=1,MAX(IF(Assumptions!$B$78=1,Assumptions!E12,Assumptions!B12),Assumptions!B104),IF(Assumptions!$B$78=1,Assumptions!E12,Assumptions!B12))))*IF(Assumptions!$B$78=1,Assumptions!E17,Assumptions!B17)*(1-0.3)+(1000*(Assumptions!B7)*(IF(Assumptions!$B$78=1,Assumptions!E13,Assumptions!B13)))*IF(Assumptions!$B$78=1,Assumptions!E18,Assumptions!B18)*(1-0.6)),0) -> 17998 | D14: =ROUND(((10000*(IF(Assumptions!$B$82=1,Assumptions!B102,Assumptions!B5))*(IF(Assumptions!$B$78=1,Assumptions!E11,Assumptions!B11)))*IF(Assumptions!$B$78=1,Assumptions!E16,Assumptions!B16)*(1-0.05)+(10000*(IF(Assumptions!$B$82=1,Assumptions!B103,Assumptions!B6))*(IF(Assumptions!$B$82=1,MAX(IF(Assumptions!$B$78=1,Assumptions!E12,Assumptions!B12),Assumptions!B104),IF(Assumptions!$B$78=1,Assumptions!E12,Assumptions!B12))))*IF(Assumptions!$B$78=1,Assumptions!E17,Assumptions!B17)*(1-0.3)+(10000*(Assumptions!B7)*(IF(Assumptions!$B$78=1,Assumptions!E13,Assumptions!B13)))*IF(Assumptions!$B$78=1,Assumptions!E18,Assumptions!B18)*(1-0.6)),0) -> 179975 | E14: =ROUND(((30000*(IF(Assumptions!$B$82=1,Assumptions!B102,Assumptions!B5))*(IF(Assumptions!$B$78=1,Assumptions!E11,Assumptions!B11)))*IF(Assumptions!$B$78=1,Assumptions!E16,Assumptions!B16)*(1-0.05)+(30000*(IF(Assumptions!$B$82=1,Assumptions!B103,Assumptions!B6))*(IF(Assumptions!$B$82=1,MAX(IF(Assumptions!$B$78=1,Assumptions!E12,Assumptions!B12),Assumptions!B104),IF(Assumptions!$B$78=1,Assumptions!E12,Assumptions!B12))))*IF(Assumptions!$B$78=1,Assumptions!E17,Assumptions!B17)*(1-0.3)+(30000*(Assumptions!B7)*(IF(Assumptions!$B$78=1,Assumptions!E13,Assumptions!B13)))*IF(Assumptions!$B$78=1,Assumptions!E18,Assumptions!B18)*(1-0.6)),0) -> 539925
A15: On-demand gross retail (mo) | B15: =ROUND((((100*(IF(Assumptions!$B$82=1,Assumptions!B102,Assumptions!B5))*(IF(Assumptions!$B$78=1,Assumptions!E11,Assumptions!B11)))*IF(Assumptions!$B$78=1,Assumptions!E16,Assumptions!B16)*(1-0.05)+(100*(IF(Assumptions!$B$82=1,Assumptions!B103,Assumptions!B6))*(IF(Assumptions!$B$82=1,MAX(IF(Assumptions!$B$78=1,Assumptions!E12,Assumptions!B12),Assumptions!B104),IF(Assumptions!$B$78=1,Assumptions!E12,Assumptions!B12))))*IF(Assumptions!$B$78=1,Assumptions!E17,Assumptions!B17)*(1-0.3)+(100*(Assumptions!B7)*(IF(Assumptions!$B$78=1,Assumptions!E13,Assumptions!B13)))*IF(Assumptions!$B$78=1,Assumptions!E18,Assumptions!B18)*(1-0.6)))*Assumptions!B48,0) -> 53993 | C15: =ROUND((((1000*(IF(Assumptions!$B$82=1,Assumptions!B102,Assumptions!B5))*(IF(Assumptions!$B$78=1,Assumptions!E11,Assumptions!B11)))*IF(Assumptions!$B$78=1,Assumptions!E16,Assumptions!B16)*(1-0.05)+(1000*(IF(Assumptions!$B$82=1,Assumptions!B103,Assumptions!B6))*(IF(Assumptions!$B$82=1,MAX(IF(Assumptions!$B$78=1,Assumptions!E12,Assumptions!B12),Assumptions!B104),IF(Assumptions!$B$78=1,Assumptions!E12,Assumptions!B12))))*IF(Assumptions!$B$78=1,Assumptions!E17,Assumptions!B17)*(1-0.3)+(1000*(Assumptions!B7)*(IF(Assumptions!$B$78=1,Assumptions!E13,Assumptions!B13)))*IF(Assumptions!$B$78=1,Assumptions!E18,Assumptions!B18)*(1-0.6)))*Assumptions!B48,0) -> 539925 | D15: =ROUND((((10000*(IF(Assumptions!$B$82=1,Assumptions!B102,Assumptions!B5))*(IF(Assumptions!$B$78=1,Assumptions!E11,Assumptions!B11)))*IF(Assumptions!$B$78=1,Assumptions!E16,Assumptions!B16)*(1-0.05)+(10000*(IF(Assumptions!$B$82=1,Assumptions!B103,Assumptions!B6))*(IF(Assumptions!$B$82=1,MAX(IF(Assumptions!$B$78=1,Assumptions!E12,Assumptions!B12),Assumptions!B104),IF(Assumptions!$B$78=1,Assumptions!E12,Assumptions!B12))))*IF(Assumptions!$B$78=1,Assumptions!E17,Assumptions!B17)*(1-0.3)+(10000*(Assumptions!B7)*(IF(Assumptions!$B$78=1,Assumptions!E13,Assumptions!B13)))*IF(Assumptions!$B$78=1,Assumptions!E18,Assumptions!B18)*(1-0.6)))*Assumptions!B48,0) -> 5399250 | E15: =ROUND((((30000*(IF(Assumptions!$B$82=1,Assumptions!B102,Assumptions!B5))*(IF(Assumptions!$B$78=1,Assumptions!E11,Assumptions!B11)))*IF(Assumptions!$B$78=1,Assumptions!E16,Assumptions!B16)*(1-0.05)+(30000*(IF(Assumptions!$B$82=1,Assumptions!B103,Assumptions!B6))*(IF(Assumptions!$B$82=1,MAX(IF(Assumptions!$B$78=1,Assumptions!E12,Assumptions!B12),Assumptions!B104),IF(Assumptions!$B$78=1,Assumptions!E12,Assumptions!B12))))*IF(Assumptions!$B$78=1,Assumptions!E17,Assumptions!B17)*(1-0.3)+(30000*(Assumptions!B7)*(IF(Assumptions!$B$78=1,Assumptions!E13,Assumptions!B13)))*IF(Assumptions!$B$78=1,Assumptions!E18,Assumptions!B18)*(1-0.6)))*Assumptions!B48,0) -> 16197750
A16: Creator-side on-demand fee | B16: =ROUND(((100*(IF(Assumptions!$B$82=1,Assumptions!B102,Assumptions!B5))*(IF(Assumptions!$B$78=1,Assumptions!E11,Assumptions!B11)))*IF(Assumptions!$B$78=1,Assumptions!E16,Assumptions!B16)*(1-0.05))*Assumptions!B48*SUMPRODUCT((Assumptions!C32:C36+Assumptions!B79/100),IF(Assumptions!$B$78=1,Assumptions!F40:F44,Assumptions!B40:B44))+((100*(IF(Assumptions!$B$82=1,Assumptions!B103,Assumptions!B6))*(IF(Assumptions!$B$82=1,MAX(IF(Assumptions!$B$78=1,Assumptions!E12,Assumptions!B12),Assumptions!B104),IF(Assumptions!$B$78=1,Assumptions!E12,Assumptions!B12))))*IF(Assumptions!$B$78=1,Assumptions!E17,Assumptions!B17)*(1-0.3))*Assumptions!B48*SUMPRODUCT((Assumptions!D32:D36+Assumptions!B79/100),IF(Assumptions!$B$78=1,Assumptions!G40:G44,Assumptions!C40:C44))+((100*(Assumptions!B7)*(IF(Assumptions!$B$78=1,Assumptions!E13,Assumptions!B13)))*IF(Assumptions!$B$78=1,Assumptions!E18,Assumptions!B18)*(1-0.6))*Assumptions!B48*SUMPRODUCT((Assumptions!E32:E36+Assumptions!B79/100),IF(Assumptions!$B$78=1,Assumptions!H40:H44,Assumptions!D40:D44)),0) -> 4340 | C16: =ROUND(((1000*(IF(Assumptions!$B$82=1,Assumptions!B102,Assumptions!B5))*(IF(Assumptions!$B$78=1,Assumptions!E11,Assumptions!B11)))*IF(Assumptions!$B$78=1,Assumptions!E16,Assumptions!B16)*(1-0.05))*Assumptions!B48*SUMPRODUCT((Assumptions!C32:C36+Assumptions!B79/100),IF(Assumptions!$B$78=1,Assumptions!F40:F44,Assumptions!B40:B44))+((1000*(IF(Assumptions!$B$82=1,Assumptions!B103,Assumptions!B6))*(IF(Assumptions!$B$82=1,MAX(IF(Assumptions!$B$78=1,Assumptions!E12,Assumptions!B12),Assumptions!B104),IF(Assumptions!$B$78=1,Assumptions!E12,Assumptions!B12))))*IF(Assumptions!$B$78=1,Assumptions!E17,Assumptions!B17)*(1-0.3))*Assumptions!B48*SUMPRODUCT((Assumptions!D32:D36+Assumptions!B79/100),IF(Assumptions!$B$78=1,Assumptions!G40:G44,Assumptions!C40:C44))+((1000*(Assumptions!B7)*(IF(Assumptions!$B$78=1,Assumptions!E13,Assumptions!B13)))*IF(Assumptions!$B$78=1,Assumptions!E18,Assumptions!B18)*(1-0.6))*Assumptions!B48*SUMPRODUCT((Assumptions!E32:E36+Assumptions!B79/100),IF(Assumptions!$B$78=1,Assumptions!H40:H44,Assumptions!D40:D44)),0) -> 43400 | D16: =ROUND(((10000*(IF(Assumptions!$B$82=1,Assumptions!B102,Assumptions!B5))*(IF(Assumptions!$B$78=1,Assumptions!E11,Assumptions!B11)))*IF(Assumptions!$B$78=1,Assumptions!E16,Assumptions!B16)*(1-0.05))*Assumptions!B48*SUMPRODUCT((Assumptions!C32:C36+Assumptions!B79/100),IF(Assumptions!$B$78=1,Assumptions!F40:F44,Assumptions!B40:B44))+((10000*(IF(Assumptions!$B$82=1,Assumptions!B103,Assumptions!B6))*(IF(Assumptions!$B$82=1,MAX(IF(Assumptions!$B$78=1,Assumptions!E12,Assumptions!B12),Assumptions!B104),IF(Assumptions!$B$78=1,Assumptions!E12,Assumptions!B12))))*IF(Assumptions!$B$78=1,Assumptions!E17,Assumptions!B17)*(1-0.3))*Assumptions!B48*SUMPRODUCT((Assumptions!D32:D36+Assumptions!B79/100),IF(Assumptions!$B$78=1,Assumptions!G40:G44,Assumptions!C40:C44))+((10000*(Assumptions!B7)*(IF(Assumptions!$B$78=1,Assumptions!E13,Assumptions!B13)))*IF(Assumptions!$B$78=1,Assumptions!E18,Assumptions!B18)*(1-0.6))*Assumptions!B48*SUMPRODUCT((Assumptions!E32:E36+Assumptions!B79/100),IF(Assumptions!$B$78=1,Assumptions!H40:H44,Assumptions!D40:D44)),0) -> 434004 | E16: =ROUND(((30000*(IF(Assumptions!$B$82=1,Assumptions!B102,Assumptions!B5))*(IF(Assumptions!$B$78=1,Assumptions!E11,Assumptions!B11)))*IF(Assumptions!$B$78=1,Assumptions!E16,Assumptions!B16)*(1-0.05))*Assumptions!B48*SUMPRODUCT((Assumptions!C32:C36+Assumptions!B79/100),IF(Assumptions!$B$78=1,Assumptions!F40:F44,Assumptions!B40:B44))+((30000*(IF(Assumptions!$B$82=1,Assumptions!B103,Assumptions!B6))*(IF(Assumptions!$B$82=1,MAX(IF(Assumptions!$B$78=1,Assumptions!E12,Assumptions!B12),Assumptions!B104),IF(Assumptions!$B$78=1,Assumptions!E12,Assumptions!B12))))*IF(Assumptions!$B$78=1,Assumptions!E17,Assumptions!B17)*(1-0.3))*Assumptions!B48*SUMPRODUCT((Assumptions!D32:D36+Assumptions!B79/100),IF(Assumptions!$B$78=1,Assumptions!G40:G44,Assumptions!C40:C44))+((30000*(Assumptions!B7)*(IF(Assumptions!$B$78=1,Assumptions!E13,Assumptions!B13)))*IF(Assumptions!$B$78=1,Assumptions!E18,Assumptions!B18)*(1-0.6))*Assumptions!B48*SUMPRODUCT((Assumptions!E32:E36+Assumptions!B79/100),IF(Assumptions!$B$78=1,Assumptions!H40:H44,Assumptions!D40:D44)),0) -> 1302013
A17: Partner-side on-demand fee | B17: =ROUND((((100*(IF(Assumptions!$B$82=1,Assumptions!B102,Assumptions!B5))*(IF(Assumptions!$B$78=1,Assumptions!E11,Assumptions!B11)))*IF(Assumptions!$B$78=1,Assumptions!E16,Assumptions!B16)*(1-0.05)+(100*(IF(Assumptions!$B$82=1,Assumptions!B103,Assumptions!B6))*(IF(Assumptions!$B$82=1,MAX(IF(Assumptions!$B$78=1,Assumptions!E12,Assumptions!B12),Assumptions!B104),IF(Assumptions!$B$78=1,Assumptions!E12,Assumptions!B12))))*IF(Assumptions!$B$78=1,Assumptions!E17,Assumptions!B17)*(1-0.3)+(100*(Assumptions!B7)*(IF(Assumptions!$B$78=1,Assumptions!E13,Assumptions!B13)))*IF(Assumptions!$B$78=1,Assumptions!E18,Assumptions!B18)*(1-0.6)))*Assumptions!B49*(Assumptions!B55*Assumptions!B58+Assumptions!B56*Assumptions!B59+Assumptions!B57*Assumptions!B60),0) -> 644 | C17: =ROUND((((1000*(IF(Assumptions!$B$82=1,Assumptions!B102,Assumptions!B5))*(IF(Assumptions!$B$78=1,Assumptions!E11,Assumptions!B11)))*IF(Assumptions!$B$78=1,Assumptions!E16,Assumptions!B16)*(1-0.05)+(1000*(IF(Assumptions!$B$82=1,Assumptions!B103,Assumptions!B6))*(IF(Assumptions!$B$82=1,MAX(IF(Assumptions!$B$78=1,Assumptions!E12,Assumptions!B12),Assumptions!B104),IF(Assumptions!$B$78=1,Assumptions!E12,Assumptions!B12))))*IF(Assumptions!$B$78=1,Assumptions!E17,Assumptions!B17)*(1-0.3)+(1000*(Assumptions!B7)*(IF(Assumptions!$B$78=1,Assumptions!E13,Assumptions!B13)))*IF(Assumptions!$B$78=1,Assumptions!E18,Assumptions!B18)*(1-0.6)))*Assumptions!B49*(Assumptions!B55*Assumptions!B58+Assumptions!B56*Assumptions!B59+Assumptions!B57*Assumptions!B60),0) -> 6443 | D17: =ROUND((((10000*(IF(Assumptions!$B$82=1,Assumptions!B102,Assumptions!B5))*(IF(Assumptions!$B$78=1,Assumptions!E11,Assumptions!B11)))*IF(Assumptions!$B$78=1,Assumptions!E16,Assumptions!B16)*(1-0.05)+(10000*(IF(Assumptions!$B$82=1,Assumptions!B103,Assumptions!B6))*(IF(Assumptions!$B$82=1,MAX(IF(Assumptions!$B$78=1,Assumptions!E12,Assumptions!B12),Assumptions!B104),IF(Assumptions!$B$78=1,Assumptions!E12,Assumptions!B12))))*IF(Assumptions!$B$78=1,Assumptions!E17,Assumptions!B17)*(1-0.3)+(10000*(Assumptions!B7)*(IF(Assumptions!$B$78=1,Assumptions!E13,Assumptions!B13)))*IF(Assumptions!$B$78=1,Assumptions!E18,Assumptions!B18)*(1-0.6)))*Assumptions!B49*(Assumptions!B55*Assumptions!B58+Assumptions!B56*Assumptions!B59+Assumptions!B57*Assumptions!B60),0) -> 64431 | E17: =ROUND((((30000*(IF(Assumptions!$B$82=1,Assumptions!B102,Assumptions!B5))*(IF(Assumptions!$B$78=1,Assumptions!E11,Assumptions!B11)))*IF(Assumptions!$B$78=1,Assumptions!E16,Assumptions!B16)*(1-0.05)+(30000*(IF(Assumptions!$B$82=1,Assumptions!B103,Assumptions!B6))*(IF(Assumptions!$B$82=1,MAX(IF(Assumptions!$B$78=1,Assumptions!E12,Assumptions!B12),Assumptions!B104),IF(Assumptions!$B$78=1,Assumptions!E12,Assumptions!B12))))*IF(Assumptions!$B$78=1,Assumptions!E17,Assumptions!B17)*(1-0.3)+(30000*(Assumptions!B7)*(IF(Assumptions!$B$78=1,Assumptions!E13,Assumptions!B13)))*IF(Assumptions!$B$78=1,Assumptions!E18,Assumptions!B18)*(1-0.6)))*Assumptions!B49*(Assumptions!B55*Assumptions!B58+Assumptions!B56*Assumptions!B59+Assumptions!B57*Assumptions!B60),0) -> 193293
A19: Bulk units (mo) | B19: =ROUND(((100*(IF(Assumptions!$B$82=1,Assumptions!B102,Assumptions!B5))*(IF(Assumptions!$B$78=1,Assumptions!E11,Assumptions!B11)))*IF(Assumptions!$B$78=1,Assumptions!G21,Assumptions!B21)*Assumptions!D21+(100*(IF(Assumptions!$B$82=1,Assumptions!B103,Assumptions!B6))*(IF(Assumptions!$B$82=1,MAX(IF(Assumptions!$B$78=1,Assumptions!E12,Assumptions!B12),Assumptions!B104),IF(Assumptions!$B$78=1,Assumptions!E12,Assumptions!B12))))*IF(Assumptions!$B$78=1,Assumptions!G22,Assumptions!B22)*Assumptions!D22+(100*(Assumptions!B7)*(IF(Assumptions!$B$78=1,Assumptions!E13,Assumptions!B13)))*IF(Assumptions!$B$78=1,Assumptions!G23,Assumptions!B23)*Assumptions!D23),0) -> 34420 | C19: =ROUND(((1000*(IF(Assumptions!$B$82=1,Assumptions!B102,Assumptions!B5))*(IF(Assumptions!$B$78=1,Assumptions!E11,Assumptions!B11)))*IF(Assumptions!$B$78=1,Assumptions!G21,Assumptions!B21)*Assumptions!D21+(1000*(IF(Assumptions!$B$82=1,Assumptions!B103,Assumptions!B6))*(IF(Assumptions!$B$82=1,MAX(IF(Assumptions!$B$78=1,Assumptions!E12,Assumptions!B12),Assumptions!B104),IF(Assumptions!$B$78=1,Assumptions!E12,Assumptions!B12))))*IF(Assumptions!$B$78=1,Assumptions!G22,Assumptions!B22)*Assumptions!D22+(1000*(Assumptions!B7)*(IF(Assumptions!$B$78=1,Assumptions!E13,Assumptions!B13)))*IF(Assumptions!$B$78=1,Assumptions!G23,Assumptions!B23)*Assumptions!D23),0) -> 344200 | D19: =ROUND(((10000*(IF(Assumptions!$B$82=1,Assumptions!B102,Assumptions!B5))*(IF(Assumptions!$B$78=1,Assumptions!E11,Assumptions!B11)))*IF(Assumptions!$B$78=1,Assumptions!G21,Assumptions!B21)*Assumptions!D21+(10000*(IF(Assumptions!$B$82=1,Assumptions!B103,Assumptions!B6))*(IF(Assumptions!$B$82=1,MAX(IF(Assumptions!$B$78=1,Assumptions!E12,Assumptions!B12),Assumptions!B104),IF(Assumptions!$B$78=1,Assumptions!E12,Assumptions!B12))))*IF(Assumptions!$B$78=1,Assumptions!G22,Assumptions!B22)*Assumptions!D22+(10000*(Assumptions!B7)*(IF(Assumptions!$B$78=1,Assumptions!E13,Assumptions!B13)))*IF(Assumptions!$B$78=1,Assumptions!G23,Assumptions!B23)*Assumptions!D23),0) -> 3442000 | E19: =ROUND(((30000*(IF(Assumptions!$B$82=1,Assumptions!B102,Assumptions!B5))*(IF(Assumptions!$B$78=1,Assumptions!E11,Assumptions!B11)))*IF(Assumptions!$B$78=1,Assumptions!G21,Assumptions!B21)*Assumptions!D21+(30000*(IF(Assumptions!$B$82=1,Assumptions!B103,Assumptions!B6))*(IF(Assumptions!$B$82=1,MAX(IF(Assumptions!$B$78=1,Assumptions!E12,Assumptions!B12),Assumptions!B104),IF(Assumptions!$B$78=1,Assumptions!E12,Assumptions!B12))))*IF(Assumptions!$B$78=1,Assumptions!G22,Assumptions!B22)*Assumptions!D22+(30000*(Assumptions!B7)*(IF(Assumptions!$B$78=1,Assumptions!E13,Assumptions!B13)))*IF(Assumptions!$B$78=1,Assumptions!G23,Assumptions!B23)*Assumptions!D23),0) -> 10326000
A20: Bulk partner cost flow (mo) | B20: =ROUND((((100*(IF(Assumptions!$B$82=1,Assumptions!B102,Assumptions!B5))*(IF(Assumptions!$B$78=1,Assumptions!E11,Assumptions!B11)))*IF(Assumptions!$B$78=1,Assumptions!G21,Assumptions!B21)*Assumptions!D21+(100*(IF(Assumptions!$B$82=1,Assumptions!B103,Assumptions!B6))*(IF(Assumptions!$B$82=1,MAX(IF(Assumptions!$B$78=1,Assumptions!E12,Assumptions!B12),Assumptions!B104),IF(Assumptions!$B$78=1,Assumptions!E12,Assumptions!B12))))*IF(Assumptions!$B$78=1,Assumptions!G22,Assumptions!B22)*Assumptions!D22+(100*(Assumptions!B7)*(IF(Assumptions!$B$78=1,Assumptions!E13,Assumptions!B13)))*IF(Assumptions!$B$78=1,Assumptions!G23,Assumptions!B23)*Assumptions!D23))*Assumptions!B51,0) -> 154890 | C20: =ROUND((((1000*(IF(Assumptions!$B$82=1,Assumptions!B102,Assumptions!B5))*(IF(Assumptions!$B$78=1,Assumptions!E11,Assumptions!B11)))*IF(Assumptions!$B$78=1,Assumptions!G21,Assumptions!B21)*Assumptions!D21+(1000*(IF(Assumptions!$B$82=1,Assumptions!B103,Assumptions!B6))*(IF(Assumptions!$B$82=1,MAX(IF(Assumptions!$B$78=1,Assumptions!E12,Assumptions!B12),Assumptions!B104),IF(Assumptions!$B$78=1,Assumptions!E12,Assumptions!B12))))*IF(Assumptions!$B$78=1,Assumptions!G22,Assumptions!B22)*Assumptions!D22+(1000*(Assumptions!B7)*(IF(Assumptions!$B$78=1,Assumptions!E13,Assumptions!B13)))*IF(Assumptions!$B$78=1,Assumptions!G23,Assumptions!B23)*Assumptions!D23))*Assumptions!B51,0) -> 1548900 | D20: =ROUND((((10000*(IF(Assumptions!$B$82=1,Assumptions!B102,Assumptions!B5))*(IF(Assumptions!$B$78=1,Assumptions!E11,Assumptions!B11)))*IF(Assumptions!$B$78=1,Assumptions!G21,Assumptions!B21)*Assumptions!D21+(10000*(IF(Assumptions!$B$82=1,Assumptions!B103,Assumptions!B6))*(IF(Assumptions!$B$82=1,MAX(IF(Assumptions!$B$78=1,Assumptions!E12,Assumptions!B12),Assumptions!B104),IF(Assumptions!$B$78=1,Assumptions!E12,Assumptions!B12))))*IF(Assumptions!$B$78=1,Assumptions!G22,Assumptions!B22)*Assumptions!D22+(10000*(Assumptions!B7)*(IF(Assumptions!$B$78=1,Assumptions!E13,Assumptions!B13)))*IF(Assumptions!$B$78=1,Assumptions!G23,Assumptions!B23)*Assumptions!D23))*Assumptions!B51,0) -> 15489000 | E20: =ROUND((((30000*(IF(Assumptions!$B$82=1,Assumptions!B102,Assumptions!B5))*(IF(Assumptions!$B$78=1,Assumptions!E11,Assumptions!B11)))*IF(Assumptions!$B$78=1,Assumptions!G21,Assumptions!B21)*Assumptions!D21+(30000*(IF(Assumptions!$B$82=1,Assumptions!B103,Assumptions!B6))*(IF(Assumptions!$B$82=1,MAX(IF(Assumptions!$B$78=1,Assumptions!E12,Assumptions!B12),Assumptions!B104),IF(Assumptions!$B$78=1,Assumptions!E12,Assumptions!B12))))*IF(Assumptions!$B$78=1,Assumptions!G22,Assumptions!B22)*Assumptions!D22+(30000*(Assumptions!B7)*(IF(Assumptions!$B$78=1,Assumptions!E13,Assumptions!B13)))*IF(Assumptions!$B$78=1,Assumptions!G23,Assumptions!B23)*Assumptions!D23))*Assumptions!B51,0) -> 46467000
A21: Creator-side bulk fee | B21: =ROUND(((100*(IF(Assumptions!$B$82=1,Assumptions!B102,Assumptions!B5))*(IF(Assumptions!$B$78=1,Assumptions!E11,Assumptions!B11)))*IF(Assumptions!$B$78=1,Assumptions!G21,Assumptions!B21)*Assumptions!D21)*Assumptions!B51*SUMPRODUCT((Assumptions!C32:C36+Assumptions!B79/100),IF(Assumptions!$B$78=1,Assumptions!F40:F44,Assumptions!B40:B44))+((100*(IF(Assumptions!$B$82=1,Assumptions!B103,Assumptions!B6))*(IF(Assumptions!$B$82=1,MAX(IF(Assumptions!$B$78=1,Assumptions!E12,Assumptions!B12),Assumptions!B104),IF(Assumptions!$B$78=1,Assumptions!E12,Assumptions!B12))))*IF(Assumptions!$B$78=1,Assumptions!G22,Assumptions!B22)*Assumptions!D22)*Assumptions!B51*SUMPRODUCT((Assumptions!D32:D36+Assumptions!B79/100),IF(Assumptions!$B$78=1,Assumptions!G40:G44,Assumptions!C40:C44))+((100*(Assumptions!B7)*(IF(Assumptions!$B$78=1,Assumptions!E13,Assumptions!B13)))*IF(Assumptions!$B$78=1,Assumptions!G23,Assumptions!B23)*Assumptions!D23)*Assumptions!B51*SUMPRODUCT((Assumptions!E32:E36+Assumptions!B79/100),IF(Assumptions!$B$78=1,Assumptions!H40:H44,Assumptions!D40:D44)),0) -> 10259 | C21: =ROUND(((1000*(IF(Assumptions!$B$82=1,Assumptions!B102,Assumptions!B5))*(IF(Assumptions!$B$78=1,Assumptions!E11,Assumptions!B11)))*IF(Assumptions!$B$78=1,Assumptions!G21,Assumptions!B21)*Assumptions!D21)*Assumptions!B51*SUMPRODUCT((Assumptions!C32:C36+Assumptions!B79/100),IF(Assumptions!$B$78=1,Assumptions!F40:F44,Assumptions!B40:B44))+((1000*(IF(Assumptions!$B$82=1,Assumptions!B103,Assumptions!B6))*(IF(Assumptions!$B$82=1,MAX(IF(Assumptions!$B$78=1,Assumptions!E12,Assumptions!B12),Assumptions!B104),IF(Assumptions!$B$78=1,Assumptions!E12,Assumptions!B12))))*IF(Assumptions!$B$78=1,Assumptions!G22,Assumptions!B22)*Assumptions!D22)*Assumptions!B51*SUMPRODUCT((Assumptions!D32:D36+Assumptions!B79/100),IF(Assumptions!$B$78=1,Assumptions!G40:G44,Assumptions!C40:C44))+((1000*(Assumptions!B7)*(IF(Assumptions!$B$78=1,Assumptions!E13,Assumptions!B13)))*IF(Assumptions!$B$78=1,Assumptions!G23,Assumptions!B23)*Assumptions!D23)*Assumptions!B51*SUMPRODUCT((Assumptions!E32:E36+Assumptions!B79/100),IF(Assumptions!$B$78=1,Assumptions!H40:H44,Assumptions!D40:D44)),0) -> 102588 | D21: =ROUND(((10000*(IF(Assumptions!$B$82=1,Assumptions!B102,Assumptions!B5))*(IF(Assumptions!$B$78=1,Assumptions!E11,Assumptions!B11)))*IF(Assumptions!$B$78=1,Assumptions!G21,Assumptions!B21)*Assumptions!D21)*Assumptions!B51*SUMPRODUCT((Assumptions!C32:C36+Assumptions!B79/100),IF(Assumptions!$B$78=1,Assumptions!F40:F44,Assumptions!B40:B44))+((10000*(IF(Assumptions!$B$82=1,Assumptions!B103,Assumptions!B6))*(IF(Assumptions!$B$82=1,MAX(IF(Assumptions!$B$78=1,Assumptions!E12,Assumptions!B12),Assumptions!B104),IF(Assumptions!$B$78=1,Assumptions!E12,Assumptions!B12))))*IF(Assumptions!$B$78=1,Assumptions!G22,Assumptions!B22)*Assumptions!D22)*Assumptions!B51*SUMPRODUCT((Assumptions!D32:D36+Assumptions!B79/100),IF(Assumptions!$B$78=1,Assumptions!G40:G44,Assumptions!C40:C44))+((10000*(Assumptions!B7)*(IF(Assumptions!$B$78=1,Assumptions!E13,Assumptions!B13)))*IF(Assumptions!$B$78=1,Assumptions!G23,Assumptions!B23)*Assumptions!D23)*Assumptions!B51*SUMPRODUCT((Assumptions!E32:E36+Assumptions!B79/100),IF(Assumptions!$B$78=1,Assumptions!H40:H44,Assumptions!D40:D44)),0) -> 1025884 | E21: =ROUND(((30000*(IF(Assumptions!$B$82=1,Assumptions!B102,Assumptions!B5))*(IF(Assumptions!$B$78=1,Assumptions!E11,Assumptions!B11)))*IF(Assumptions!$B$78=1,Assumptions!G21,Assumptions!B21)*Assumptions!D21)*Assumptions!B51*SUMPRODUCT((Assumptions!C32:C36+Assumptions!B79/100),IF(Assumptions!$B$78=1,Assumptions!F40:F44,Assumptions!B40:B44))+((30000*(IF(Assumptions!$B$82=1,Assumptions!B103,Assumptions!B6))*(IF(Assumptions!$B$82=1,MAX(IF(Assumptions!$B$78=1,Assumptions!E12,Assumptions!B12),Assumptions!B104),IF(Assumptions!$B$78=1,Assumptions!E12,Assumptions!B12))))*IF(Assumptions!$B$78=1,Assumptions!G22,Assumptions!B22)*Assumptions!D22)*Assumptions!B51*SUMPRODUCT((Assumptions!D32:D36+Assumptions!B79/100),IF(Assumptions!$B$78=1,Assumptions!G40:G44,Assumptions!C40:C44))+((30000*(Assumptions!B7)*(IF(Assumptions!$B$78=1,Assumptions!E13,Assumptions!B13)))*IF(Assumptions!$B$78=1,Assumptions!G23,Assumptions!B23)*Assumptions!D23)*Assumptions!B51*SUMPRODUCT((Assumptions!E32:E36+Assumptions!B79/100),IF(Assumptions!$B$78=1,Assumptions!H40:H44,Assumptions!D40:D44)),0) -> 3077652
A22: Partner-side bulk fee | B22: =ROUND((((100*(IF(Assumptions!$B$82=1,Assumptions!B102,Assumptions!B5))*(IF(Assumptions!$B$78=1,Assumptions!E11,Assumptions!B11)))*IF(Assumptions!$B$78=1,Assumptions!G21,Assumptions!B21)*Assumptions!D21+(100*(IF(Assumptions!$B$82=1,Assumptions!B103,Assumptions!B6))*(IF(Assumptions!$B$82=1,MAX(IF(Assumptions!$B$78=1,Assumptions!E12,Assumptions!B12),Assumptions!B104),IF(Assumptions!$B$78=1,Assumptions!E12,Assumptions!B12))))*IF(Assumptions!$B$78=1,Assumptions!G22,Assumptions!B22)*Assumptions!D22+(100*(Assumptions!B7)*(IF(Assumptions!$B$78=1,Assumptions!E13,Assumptions!B13)))*IF(Assumptions!$B$78=1,Assumptions!G23,Assumptions!B23)*Assumptions!D23))*Assumptions!B51*(Assumptions!B55*Assumptions!B58+Assumptions!B56*Assumptions!B59+Assumptions!B57*Assumptions!B60),0) -> 6931 | C22: =ROUND((((1000*(IF(Assumptions!$B$82=1,Assumptions!B102,Assumptions!B5))*(IF(Assumptions!$B$78=1,Assumptions!E11,Assumptions!B11)))*IF(Assumptions!$B$78=1,Assumptions!G21,Assumptions!B21)*Assumptions!D21+(1000*(IF(Assumptions!$B$82=1,Assumptions!B103,Assumptions!B6))*(IF(Assumptions!$B$82=1,MAX(IF(Assumptions!$B$78=1,Assumptions!E12,Assumptions!B12),Assumptions!B104),IF(Assumptions!$B$78=1,Assumptions!E12,Assumptions!B12))))*IF(Assumptions!$B$78=1,Assumptions!G22,Assumptions!B22)*Assumptions!D22+(1000*(Assumptions!B7)*(IF(Assumptions!$B$78=1,Assumptions!E13,Assumptions!B13)))*IF(Assumptions!$B$78=1,Assumptions!G23,Assumptions!B23)*Assumptions!D23))*Assumptions!B51*(Assumptions!B55*Assumptions!B58+Assumptions!B56*Assumptions!B59+Assumptions!B57*Assumptions!B60),0) -> 69313 | D22: =ROUND((((10000*(IF(Assumptions!$B$82=1,Assumptions!B102,Assumptions!B5))*(IF(Assumptions!$B$78=1,Assumptions!E11,Assumptions!B11)))*IF(Assumptions!$B$78=1,Assumptions!G21,Assumptions!B21)*Assumptions!D21+(10000*(IF(Assumptions!$B$82=1,Assumptions!B103,Assumptions!B6))*(IF(Assumptions!$B$82=1,MAX(IF(Assumptions!$B$78=1,Assumptions!E12,Assumptions!B12),Assumptions!B104),IF(Assumptions!$B$78=1,Assumptions!E12,Assumptions!B12))))*IF(Assumptions!$B$78=1,Assumptions!G22,Assumptions!B22)*Assumptions!D22+(10000*(Assumptions!B7)*(IF(Assumptions!$B$78=1,Assumptions!E13,Assumptions!B13)))*IF(Assumptions!$B$78=1,Assumptions!G23,Assumptions!B23)*Assumptions!D23))*Assumptions!B51*(Assumptions!B55*Assumptions!B58+Assumptions!B56*Assumptions!B59+Assumptions!B57*Assumptions!B60),0) -> 693133 | E22: =ROUND((((30000*(IF(Assumptions!$B$82=1,Assumptions!B102,Assumptions!B5))*(IF(Assumptions!$B$78=1,Assumptions!E11,Assumptions!B11)))*IF(Assumptions!$B$78=1,Assumptions!G21,Assumptions!B21)*Assumptions!D21+(30000*(IF(Assumptions!$B$82=1,Assumptions!B103,Assumptions!B6))*(IF(Assumptions!$B$82=1,MAX(IF(Assumptions!$B$78=1,Assumptions!E12,Assumptions!B12),Assumptions!B104),IF(Assumptions!$B$78=1,Assumptions!E12,Assumptions!B12))))*IF(Assumptions!$B$78=1,Assumptions!G22,Assumptions!B22)*Assumptions!D22+(30000*(Assumptions!B7)*(IF(Assumptions!$B$78=1,Assumptions!E13,Assumptions!B13)))*IF(Assumptions!$B$78=1,Assumptions!G23,Assumptions!B23)*Assumptions!D23))*Assumptions!B51*(Assumptions!B55*Assumptions!B58+Assumptions!B56*Assumptions!B59+Assumptions!B57*Assumptions!B60),0) -> 2079398
A24: Base platform take (mo) | B24: =B12+B16+B17+B21+B22 -> 24394 | C24: =C12+C16+C17+C21+C22 -> 243944 | D24: =D12+D16+D17+D21+D22 -> 2439452 | E24: =E12+E16+E17+E21+E22 -> 7318356
A26: Rec 2 — Float income | B26: =IF(Assumptions!$B$83=1,(B15+B20)*Assumptions!B93*(Assumptions!B92/365),0) -> 0 | C26: =IF(Assumptions!$B$83=1,(C15+C20)*Assumptions!B93*(Assumptions!B92/365),0) -> 0 | D26: =IF(Assumptions!$B$83=1,(D15+D20)*Assumptions!B93*(Assumptions!B92/365),0) -> 0 | E26: =IF(Assumptions!$B$83=1,(E15+E20)*Assumptions!B93*(Assumptions!B92/365),0) -> 0
A27: Rec 6 — Partner referral drag | B27: =-IF(Assumptions!$B$86=1,B24*Assumptions!B94*Assumptions!B95,0) -> 0 | C27: =-IF(Assumptions!$B$86=1,C24*Assumptions!B94*Assumptions!B95,0) -> 0 | D27: =-IF(Assumptions!$B$86=1,D24*Assumptions!B94*Assumptions!B95,0) -> 0 | E27: =-IF(Assumptions!$B$86=1,E24*Assumptions!B94*Assumptions!B95,0) -> 0
A28: Rec 7 — Premium AI overage | B28: =IF(Assumptions!$B$87=1,(B10+B11)*Assumptions!B96*Assumptions!B97*(Assumptions!B98-Assumptions!B99),0) -> 0 | C28: =IF(Assumptions!$B$87=1,(C10+C11)*Assumptions!B96*Assumptions!B97*(Assumptions!B98-Assumptions!B99),0) -> 0 | D28: =IF(Assumptions!$B$87=1,(D10+D11)*Assumptions!B96*Assumptions!B97*(Assumptions!B98-Assumptions!B99),0) -> 0 | E28: =IF(Assumptions!$B$87=1,(E10+E11)*Assumptions!B96*Assumptions!B97*(Assumptions!B98-Assumptions!B99),0) -> 0
A29: Rec 8 — Bulk escrow | B29: =IF(Assumptions!$B$88=1,B20*Assumptions!B100*Assumptions!B101,0) -> 0 | C29: =IF(Assumptions!$B$88=1,C20*Assumptions!B100*Assumptions!B101,0) -> 0 | D29: =IF(Assumptions!$B$88=1,D20*Assumptions!B100*Assumptions!B101,0) -> 0 | E29: =IF(Assumptions!$B$88=1,E20*Assumptions!B100*Assumptions!B101,0) -> 0
A31: Total platform take (mo) | B31: =B24+B26+B27+B28+B29 -> 24394 | C31: =C24+C26+C27+C28+C29 -> 243944 | D31: =D24+D26+D27+D28+D29 -> 2439452 | E31: =E24+E26+E27+E28+E29 -> 7318356
A33: Stripe Connect costs | B33: =ROUND((B14+B19/500)*Assumptions!B66+(B15+B20)*Assumptions!B65,0) -> 989 | C33: =ROUND((C14+C19/500)*Assumptions!B66+(C15+C20)*Assumptions!B65,0) -> 9894 | D33: =ROUND((D14+D19/500)*Assumptions!B66+(D15+D20)*Assumptions!B65,0) -> 98935 | E33: =ROUND((E14+E19/500)*Assumptions!B66+(E15+E20)*Assumptions!B65,0) -> 296806
A34: AI parser cost | B34: =ROUND(B10*Assumptions!B68*Assumptions!B67+B11*Assumptions!B69*Assumptions!B67,0) -> 570 | C34: =ROUND(C10*Assumptions!B68*Assumptions!B67+C11*Assumptions!B69*Assumptions!B67,0) -> 5325 | D34: =ROUND(D10*Assumptions!B68*Assumptions!B67+D11*Assumptions!B69*Assumptions!B67,0) -> 53250 | E34: =ROUND(E10*Assumptions!B68*Assumptions!B67+E11*Assumptions!B69*Assumptions!B67,0) -> 159750
A35: Asset library (Shutterstock) | B35: =Assumptions!B70 -> 300 | C35: =Assumptions!B70 -> 300 | D35: =Assumptions!B70 -> 300 | E35: =Assumptions!B70 -> 300
A36: Fixed opex (monthly) | B36: =Assumptions!B71/12 -> 2083.3333 | C36: =Assumptions!B72/12 -> 6250 | D36: =Assumptions!B73/12 -> 20833.333 | E36: =Assumptions!B74/12 -> 50000
A38: Operating profit (monthly) | B38: =B31-(B33+B34+B35+B36) -> 20451.667 | C38: =C31-(C33+C34+C35+C36) -> 222175 | D38: =D31-(D33+D34+D35+D36) -> 2266133.7 | E38: =E31-(E33+E34+E35+E36) -> 6811500
A39: Annualized revenue (ARR) | B39: =B31*12 -> 292728 | C39: =C31*12 -> 2927328 | D39: =D31*12 -> 29273424 | E39: =E31*12 -> 87820272
A40: Annualized op profit | B40: =B38*12 -> 245420 | C40: =C38*12 -> 2666100 | D40: =D38*12 -> 27193604 | E40: =E38*12 -> 81738000

Sheet Dashboard
A1: DASHBOARD — live headline numbers
A2: Toggle scenarios on Assumptions sheet. This dashboard reflects the active configuration.
A4: Active scenario: | B4: =IF(Assumptions!B78=1,"Conservative","Base") & " demand, +" & TEXT(Assumptions!B79,"0") & "pp uplift" -> Base demand, +0pp uplift
A5: Recs active: | B5: ="Rec1=" & Assumptions!B82 & " Rec2=" & Assumptions!B83 & " Rec3=" & Assumptions!B84 & " Rec6=" & Assumptions!B86 & " Rec7=" & Assumptions!B87 & " Rec8=" & Assumptions!B88 -> Rec1=0 Rec2=0 Rec3=0 Rec6=0 Rec7=0 Rec8=0
A7: Scale | B7: Annualized revenue | C7: Operating profit | D7: Profit / creator / yr
A8: 100 creators | B8: =Results!B39 -> 292728 | C8: =Results!B40 -> 245420 | D8: =Results!B40/100 -> 2454.2
A9: 1,000 creators | B9: =Results!C39 -> 2927328 | C9: =Results!C40 -> 2666100 | D9: =Results!C40/1000 -> 2666.1
A10: 10,000 creators | B10: =Results!D39 -> 29273424 | C10: =Results!D40 -> 27193604 | D10: =Results!D40/10000 -> 2719.3604
A11: 30,000 creators | B11: =Results!E39 -> 87820272 | C11: =Results!E40 -> 81738000 | D11: =Results!E40/30000 -> 2724.6
A13: Effective fees (volume-weighted)
A14: Maker | B14: =SUMPRODUCT(Assumptions!C32:C36+Assumptions!B79/100,IF(Assumptions!B78=1,Assumptions!F40:F44,Assumptions!B40:B44)) -> 0.1476
A15: Builder | B15: =SUMPRODUCT(Assumptions!D32:D36+Assumptions!B79/100,IF(Assumptions!B78=1,Assumptions!G40:G44,Assumptions!C40:C44)) -> 0.08925
A16: Agency | B16: =SUMPRODUCT(Assumptions!E32:E36+Assumptions!B79/100,IF(Assumptions!B78=1,Assumptions!H40:H44,Assumptions!D40:D44)) -> 0.059
A17: Partner avg | B17: =Assumptions!B55*Assumptions!B58+Assumptions!B56*Assumptions!B59+Assumptions!B57*Assumptions!B60 -> 0.04475

Sheet README
A1: HOW TO USE THIS LIVE MODEL
A3: WHAT THIS IS
A4: One master live model that supersedes the 5 prior static spreadsheets. Every yellow cell on Assumptions is an input. Every white
A5: cell is a formula. Edit any input — the model recalculates everywhere.
A7: QUICK SCENARIO TOGGLES (on Assumptions sheet)
A8: Cell B78 — Use Conservative demand? 0 = Base assumptions, 1 = Conservative (halved demand levers)
A9: Cell B79 — Pricing uplift (pp) 0 = locked V1.5, 5 = +5pp aggressive, 10 = +10pp ceiling test
A11: RECOMMENDATION TOGGLES (set 1 to enable)
A12: B82 — Rec 1 Engineered Maker→Builder triggers (mix shift + Builder activation lift)
A13: B83 — Rec 2 Float income on held balances
A14: B84 — Rec 3 Sub prices Builder $79 / Agency $249 (vs $49/$199)
A15: B86 — Rec 6 Partner referral commission (-2% drag)
... A47: Assumptions. There are no hidden constants beyond the bulk-share noted above.
